<?xml version="1.0" ?>
<!-- =================================================================================== -->
<!-- |    This document was autogenerated by xacro from /home/alaurenzi/code/ros2_ws/ros_src/iit-kyon-ros-pkg/kyon_urdf/urdf/kyon.urdf.xacro | -->
<!-- |    EDITING THIS FILE BY HAND IS NOT RECOMMENDED                                 | -->
<!-- =================================================================================== -->

    <robot name="kyon">
    <mujoco>
        <compiler strippath="false"/>
    </mujoco>
    
  <!-- scaling factor for available peack torque link side, from 0 to 1 -->
  <material name="black">
    <color rgba="0.4 0.4 0.4 1"/>
  </material>
  <material name="dark_grey">
    <color rgba="0.1 0.1 0.1 1"/>
  </material>
  <material name="light_grey">
    <color rgba="0.2 0.2 0.2 1"/>
  </material>
  <material name="kyon_orange">
    <color rgba="0.925 0.325 0.0 1"/>
  </material>
  <!-- Compound properties (i.e. based on the props parsed from the yaml) -->
  <link name="base_link"/>
  <link name="pelvis">
    <inertial>
      <origin xyz="0.056500758 0.002091838 0.086799843"/>
      <mass value="19.962822"/>
      <inertia ixx="0.24817282999999998" ixy="-0.0041644587" ixz="-0.060913554999999994" iyy="1.2563811999999999" iyz="0.00024917702" izz="1.2495441"/>
    </inertial>
    <visual>
      <origin rpy="0.0 0.0 0.0" xyz="0.0 0 0.0"/>
      <geometry>
        <mesh filename="/home/alaurenzi/code/ros2_ws/ros_src/iit-kyon-ros-pkg/kyon_urdf/meshes/mesh_pelvis.stl" scale="0.001 0.001 0.001"/>
      </geometry>
      <material name="dark_grey"/>
    </visual>
  </link>
  <link name="battery">
    <inertial>
      <mass value="9.8"/>
      <inertia ixx="0.04647935016666667" ixy="0.0" ixz="0.0" iyy="0.09353241683333333" iyz="0.0" izz="0.12974056666666667"/>
    </inertial>
    <visual>
      <geometry>
        <box size="0.329 0.225 0.0793"/>
      </geometry>
      <material name="dark_grey"/>
    </visual>
  </link>
  <joint name="battery_joint" type="fixed">
    <origin xyz="0.0 0.0 -0.02725"/>
    <parent link="pelvis"/>
    <child link="battery"/>
  </joint>
  <joint name="base_joint" type="fixed">
    <parent link="pelvis"/>
    <child link="base_link"/>
    <origin rpy="0 0 0" xyz="0 0 0"/>
  </joint>
  <link name="imu_link"/>
  <joint name="imu_joint" type="fixed">
    <origin rpy="3.14159265359 0 0" xyz="-0.256190 0 0.103"/>
    <parent link="pelvis"/>
    <child link="imu_link"/>
  </joint>
  <!-- CAMERA BASE FRAMES -->
  <link name="zed_front_up_mount_link"/>
  <joint name="zed_front_up_mount_joint" type="fixed">
    <parent link="pelvis"/>
    <child link="zed_front_up_mount_link"/>
    <origin rpy="0 -0.1745327 0" xyz="0.526174 0 0.0674608"/>
  </joint>
  <link name="zed_front_down_mount_link"/>
  <joint name="zed_front_down_mount_joint" type="fixed">
    <parent link="pelvis"/>
    <child link="zed_front_down_mount_link"/>
    <origin rpy="0 0.9250251 0" xyz="0.509601 0 0.00343992"/>
  </joint>
  <link name="left_camera_mount_link"/>
  <joint name="left_camera_mount_joint" type="fixed">
    <parent link="pelvis"/>
    <child link="left_camera_mount_link"/>
    <origin rpy="0 0.3490656 1.5707963" xyz="0 0.150100 0.109486"/>
  </joint>
  <link name="right_camera_mount_link"/>
  <joint name="right_camera_mount_joint" type="fixed">
    <parent link="pelvis"/>
    <child link="right_camera_mount_link"/>
    <origin rpy="0 0.3490656 -1.5707963" xyz="0 -0.150100 0.109486"/>
  </joint>
  <!-- Velodyne -->
  <link name="hesai_lidar"/>
  <joint name="hesai_lidar_joints" type="fixed">
    <origin rpy="0 0 0.5220063" xyz="0.43 0 0.118"/>
    <parent link="pelvis"/>
    <child link="hesai_lidar"/>
  </joint>
  <!-- /macro legs -->
  <!-- links -->
  <link name="hip_roll_1_link">
    <inertial>
      <origin xyz="-0.00067317742 0.0065349155 -0.11564663"/>
      <mass value="2.5772427"/>
      <inertia ixx="0.014198247999999998" ixy="5.199100799999999e-06" ixz="5.3090191e-05" iyy="0.014484612" iyz="0.001454582" izz="0.004551220599999999"/>
    </inertial>
    <visual>
      <origin rpy="0.0 0.0 0.0" xyz="0.0 0.0 0.0"/>
      <geometry>
        <!-- <cylinder radius="${cylinder_radius}" length="${cylinder_length}"/> -->
        <mesh filename="/home/alaurenzi/code/ros2_ws/ros_src/iit-kyon-ros-pkg/kyon_urdf/meshes/mesh_hip-roll.stl" scale="0.001 -0.001 0.001"/>
      </geometry>
      <material name="dark_grey"/>
    </visual>
  </link>
  <link name="hip_pitch_1_link">
    <inertial>
      <origin xyz="6.9653887e-05 -0.077666126 0.14689295000000002"/>
      <mass value="6.4366103"/>
      <inertia ixx="0.12144025" ixy="-0.0006467757299999999" ixz="-5.7668584e-05" iyy="0.027586780999999998" iyz="0.027586780999999998" izz="0.10048465"/>
    </inertial>
    <visual>
      <origin rpy="0.0 0.0 0.0" xyz="0.0 0.0 0.0"/>
      <geometry>
        <mesh filename="/home/alaurenzi/code/ros2_ws/ros_src/iit-kyon-ros-pkg/kyon_urdf/meshes/mesh_hip-pitch.stl" scale="0.001 0.001 0.001"/>
      </geometry>
      <material name="kyon_orange"/>
    </visual>
    <visual>
      <origin rpy="0.0 0.0 0.0" xyz="0.0 0.0 0.0"/>
      <geometry>
        <mesh filename="/home/alaurenzi/code/ros2_ws/ros_src/iit-kyon-ros-pkg/kyon_urdf/meshes/mesh_hip-pitch_cover.stl" scale="0.001 0.001 0.001"/>
      </geometry>
      <material name="dark_grey"/>
    </visual>
  </link>
  <!-- joints -->
  <joint name="hip_roll_1" type="revolute">
    <parent link="pelvis"/>
    <child link="hip_roll_1_link"/>
    <origin rpy="0.0 1.57079632679 0.0" xyz="0.391 0.0775 0.0"/>
    <axis xyz="0 0 -1"/>
    <limit effort="185" lower="-0.65" upper="0.65" velocity="7.6"/>
  </joint>
  <joint name="hip_pitch_1" type="revolute">
    <parent link="hip_roll_1_link"/>
    <child link="hip_pitch_1_link"/>
    <origin rpy="0.0 1.57079632679 1.57079632679" xyz="0.0 -0.04746 0.0"/>
    <axis xyz="0 0 -1"/>
    <limit effort="185" lower="-2.4056" upper="2.4056" velocity="7.6"/>
  </joint>
  <link name="knee_pitch_1_link">
    <inertial>
      <origin xyz="5.1193011000000004e-06 -0.10291594999999999 -0.0012895495"/>
      <mass value="0.70900216"/>
      <inertia ixx="0.012517512" ixy="5.4385779e-07" ixz="-1.4538899e-07" iyy="0.00080474409" iyz="0.001744629" izz="0.01230702"/>
    </inertial>
    <visual>
      <origin rpy="0.0 0.0 0.0" xyz="0.0 0.0 0.0"/>
      <geometry>
        <mesh filename="/home/alaurenzi/code/ros2_ws/ros_src/iit-kyon-ros-pkg/kyon_urdf/meshes/mesh_foot-leg.stl" scale="-0.001 0.001 0.001"/>
      </geometry>
      <material name="dark_grey"/>
    </visual>
  </link>
  <joint name="knee_pitch_1" type="revolute">
    <parent link="hip_pitch_1_link"/>
    <child link="knee_pitch_1_link"/>
    <origin rpy="0.0 0.0 0.0" xyz="0.0 -0.34600000000000003 0.24606"/>
    <axis xyz="0 0 -1"/>
    <limit effort="185" lower="-3.2" upper="3.2" velocity="7.6"/>
  </joint>
  <link name="contact_1">
    <visual>
      <origin rpy="0 0 0" xyz="0 0 0"/>
      <geometry>
        <sphere radius="0.03"/>
      </geometry>
      <material name="white"/>
    </visual>
    <collision name="contact_1">
      <origin rpy="0 0 0" xyz="0 0 0"/>
      <geometry>
        <sphere radius="0.03"/>
      </geometry>
    </collision>
  </link>
  <joint name="contact_1_joint" type="fixed">
    <parent link="knee_pitch_1_link"/>
    <child link="contact_1"/>
    <origin rpy="-1.57 0 0.785" xyz="0.0 -0.3 0.054"/>
  </joint>
  <!-- <xacro:if value="${ADD_WHEELS}">
    <xacro:wheel_leg leg_num="${leg_num}" parent="hip_pitch_${leg_num}_link" origin_x="${origin_x}" origin_y="${origin_y}" mirror="${mirror}"/>
</xacro:if> -->
  <!-- links -->
  <link name="hip_roll_2_link">
    <inertial>
      <origin xyz="-0.00067317742 0.0065349155 -0.11564663"/>
      <mass value="2.5772427"/>
      <inertia ixx="0.014198247999999998" ixy="-5.199100799999999e-06" ixz="5.3090191e-05" iyy="0.014484612" iyz="-0.001454582" izz="0.004551220599999999"/>
    </inertial>
    <visual>
      <origin rpy="0.0 0.0 0.0" xyz="0.0 0.0 0.0"/>
      <geometry>
        <!-- <cylinder radius="${cylinder_radius}" length="${cylinder_length}"/> -->
        <mesh filename="/home/alaurenzi/code/ros2_ws/ros_src/iit-kyon-ros-pkg/kyon_urdf/meshes/mesh_hip-roll.stl" scale="0.001 0.001 0.001"/>
      </geometry>
      <material name="dark_grey"/>
    </visual>
  </link>
  <link name="hip_pitch_2_link">
    <inertial>
      <origin xyz="6.9653887e-05 -0.077666126 0.14689295000000002"/>
      <mass value="6.4366103"/>
      <inertia ixx="0.12144025" ixy="-0.0006467757299999999" ixz="-5.7668584e-05" iyy="0.027586780999999998" iyz="0.027586780999999998" izz="0.10048465"/>
    </inertial>
    <visual>
      <origin rpy="0.0 0.0 0.0" xyz="0.0 0.0 0.0"/>
      <geometry>
        <mesh filename="/home/alaurenzi/code/ros2_ws/ros_src/iit-kyon-ros-pkg/kyon_urdf/meshes/mesh_hip-pitch.stl" scale="0.001 0.001 0.001"/>
      </geometry>
      <material name="kyon_orange"/>
    </visual>
    <visual>
      <origin rpy="0.0 0.0 0.0" xyz="0.0 0.0 0.0"/>
      <geometry>
        <mesh filename="/home/alaurenzi/code/ros2_ws/ros_src/iit-kyon-ros-pkg/kyon_urdf/meshes/mesh_hip-pitch_cover.stl" scale="0.001 0.001 0.001"/>
      </geometry>
      <material name="dark_grey"/>
    </visual>
  </link>
  <!-- joints -->
  <joint name="hip_roll_2" type="revolute">
    <parent link="pelvis"/>
    <child link="hip_roll_2_link"/>
    <origin rpy="0.0 1.57079632679 0.0" xyz="0.391 -0.0775 0.0"/>
    <axis xyz="0 0 -1"/>
    <limit effort="185" lower="-0.65" upper="0.65" velocity="7.6"/>
  </joint>
  <joint name="hip_pitch_2" type="revolute">
    <parent link="hip_roll_2_link"/>
    <child link="hip_pitch_2_link"/>
    <origin rpy="0.0 -1.57079632679 1.57079632679" xyz="0.0 0.04746 0.0"/>
    <axis xyz="0 0 -1"/>
    <limit effort="185" lower="-2.3266" upper="2.3266" velocity="7.6"/>
  </joint>
  <link name="knee_pitch_2_link">
    <inertial>
      <origin xyz="5.1193011000000004e-06 -0.10291594999999999 -0.0012895495"/>
      <mass value="0.70900216"/>
      <inertia ixx="0.012517512" ixy="-5.4385779e-07" ixz="1.4538899e-07" iyy="0.00080474409" iyz="0.001744629" izz="0.01230702"/>
    </inertial>
    <visual>
      <origin rpy="0.0 0.0 0.0" xyz="0.0 0.0 0.0"/>
      <geometry>
        <mesh filename="/home/alaurenzi/code/ros2_ws/ros_src/iit-kyon-ros-pkg/kyon_urdf/meshes/mesh_foot-leg.stl" scale="0.001 0.001 0.001"/>
      </geometry>
      <material name="dark_grey"/>
    </visual>
  </link>
  <joint name="knee_pitch_2" type="revolute">
    <parent link="hip_pitch_2_link"/>
    <child link="knee_pitch_2_link"/>
    <origin rpy="0.0 0.0 0.0" xyz="0.0 -0.34600000000000003 0.24606"/>
    <axis xyz="0 0 -1"/>
    <limit effort="185" lower="-3.2" upper="3.2" velocity="7.6"/>
  </joint>
  <link name="contact_2">
    <visual>
      <origin rpy="0 0 0" xyz="0 0 0"/>
      <geometry>
        <sphere radius="0.03"/>
      </geometry>
      <material name="white"/>
    </visual>
    <collision name="contact_2">
      <origin rpy="0 0 0" xyz="0 0 0"/>
      <geometry>
        <sphere radius="0.03"/>
      </geometry>
    </collision>
  </link>
  <joint name="contact_2_joint" type="fixed">
    <parent link="knee_pitch_2_link"/>
    <child link="contact_2"/>
    <origin rpy="1.57 0 2.356" xyz="-0.0 -0.3 0.054"/>
  </joint>
  <!-- <xacro:if value="${ADD_WHEELS}">
    <xacro:wheel_leg leg_num="${leg_num}" parent="hip_pitch_${leg_num}_link" origin_x="${origin_x}" origin_y="${origin_y}" mirror="${mirror}"/>
</xacro:if> -->
  <!-- links -->
  <link name="hip_roll_3_link">
    <inertial>
      <origin xyz="-0.00067317742 0.0065349155 -0.11564663"/>
      <mass value="2.5772427"/>
      <inertia ixx="0.014198247999999998" ixy="5.199100799999999e-06" ixz="5.3090191e-05" iyy="0.014484612" iyz="0.001454582" izz="0.004551220599999999"/>
    </inertial>
    <visual>
      <origin rpy="0.0 0.0 0.0" xyz="0.0 0.0 0.0"/>
      <geometry>
        <!-- <cylinder radius="${cylinder_radius}" length="${cylinder_length}"/> -->
        <mesh filename="/home/alaurenzi/code/ros2_ws/ros_src/iit-kyon-ros-pkg/kyon_urdf/meshes/mesh_hip-roll.stl" scale="0.001 -0.001 0.001"/>
      </geometry>
      <material name="dark_grey"/>
    </visual>
  </link>
  <link name="hip_pitch_3_link">
    <inertial>
      <origin xyz="6.9653887e-05 -0.077666126 0.14689295000000002"/>
      <mass value="6.4366103"/>
      <inertia ixx="0.12144025" ixy="-0.0006467757299999999" ixz="-5.7668584e-05" iyy="0.027586780999999998" iyz="0.027586780999999998" izz="0.10048465"/>
    </inertial>
    <visual>
      <origin rpy="0.0 0.0 0.0" xyz="0.0 0.0 0.0"/>
      <geometry>
        <mesh filename="/home/alaurenzi/code/ros2_ws/ros_src/iit-kyon-ros-pkg/kyon_urdf/meshes/mesh_hip-pitch.stl" scale="0.001 0.001 0.001"/>
      </geometry>
      <material name="kyon_orange"/>
    </visual>
    <visual>
      <origin rpy="0.0 0.0 0.0" xyz="0.0 0.0 0.0"/>
      <geometry>
        <mesh filename="/home/alaurenzi/code/ros2_ws/ros_src/iit-kyon-ros-pkg/kyon_urdf/meshes/mesh_hip-pitch_cover.stl" scale="0.001 0.001 0.001"/>
      </geometry>
      <material name="dark_grey"/>
    </visual>
  </link>
  <!-- joints -->
  <joint name="hip_roll_3" type="revolute">
    <parent link="pelvis"/>
    <child link="hip_roll_3_link"/>
    <origin rpy="0.0 -1.57079632679 0.0" xyz="-0.391 0.0775 0.0"/>
    <axis xyz="0 0 -1"/>
    <limit effort="185" lower="-0.65" upper="0.65" velocity="7.6"/>
  </joint>
  <joint name="hip_pitch_3" type="revolute">
    <parent link="hip_roll_3_link"/>
    <child link="hip_pitch_3_link"/>
    <origin rpy="0.0 -1.57079632679 -1.57079632679" xyz="0.0 -0.04746 0.0"/>
    <axis xyz="0 0 -1"/>
    <limit effort="185" lower="-2.4696" upper="2.4696" velocity="7.6"/>
  </joint>
  <link name="knee_pitch_3_link">
    <inertial>
      <origin xyz="5.1193011000000004e-06 -0.10291594999999999 -0.0012895495"/>
      <mass value="0.70900216"/>
      <inertia ixx="0.012517512" ixy="5.4385779e-07" ixz="-1.4538899e-07" iyy="0.00080474409" iyz="0.001744629" izz="0.01230702"/>
    </inertial>
    <visual>
      <origin rpy="0.0 0.0 0.0" xyz="0.0 0.0 0.0"/>
      <geometry>
        <mesh filename="/home/alaurenzi/code/ros2_ws/ros_src/iit-kyon-ros-pkg/kyon_urdf/meshes/mesh_foot-leg.stl" scale="-0.001 0.001 0.001"/>
      </geometry>
      <material name="dark_grey"/>
    </visual>
  </link>
  <joint name="knee_pitch_3" type="revolute">
    <parent link="hip_pitch_3_link"/>
    <child link="knee_pitch_3_link"/>
    <origin rpy="0.0 0.0 0.0" xyz="0.0 -0.34600000000000003 0.24606"/>
    <axis xyz="0 0 -1"/>
    <limit effort="185" lower="-3.2" upper="3.2" velocity="7.6"/>
  </joint>
  <link name="contact_3">
    <visual>
      <origin rpy="0 0 0" xyz="0 0 0"/>
      <geometry>
        <sphere radius="0.03"/>
      </geometry>
      <material name="white"/>
    </visual>
    <collision name="contact_3">
      <origin rpy="0 0 0" xyz="0 0 0"/>
      <geometry>
        <sphere radius="0.03"/>
      </geometry>
    </collision>
  </link>
  <joint name="contact_3_joint" type="fixed">
    <parent link="knee_pitch_3_link"/>
    <child link="contact_3"/>
    <origin rpy="-1.57 0 0.785" xyz="0.0 -0.3 0.054"/>
  </joint>
  <!-- <xacro:if value="${ADD_WHEELS}">
    <xacro:wheel_leg leg_num="${leg_num}" parent="hip_pitch_${leg_num}_link" origin_x="${origin_x}" origin_y="${origin_y}" mirror="${mirror}"/>
</xacro:if> -->
  <!-- links -->
  <link name="hip_roll_4_link">
    <inertial>
      <origin xyz="-0.00067317742 0.0065349155 -0.11564663"/>
      <mass value="2.5772427"/>
      <inertia ixx="0.014198247999999998" ixy="-5.199100799999999e-06" ixz="5.3090191e-05" iyy="0.014484612" iyz="-0.001454582" izz="0.004551220599999999"/>
    </inertial>
    <visual>
      <origin rpy="0.0 0.0 0.0" xyz="0.0 0.0 0.0"/>
      <geometry>
        <!-- <cylinder radius="${cylinder_radius}" length="${cylinder_length}"/> -->
        <mesh filename="/home/alaurenzi/code/ros2_ws/ros_src/iit-kyon-ros-pkg/kyon_urdf/meshes/mesh_hip-roll.stl" scale="0.001 0.001 0.001"/>
      </geometry>
      <material name="dark_grey"/>
    </visual>
  </link>
  <link name="hip_pitch_4_link">
    <inertial>
      <origin xyz="6.9653887e-05 -0.077666126 0.14689295000000002"/>
      <mass value="6.4366103"/>
      <inertia ixx="0.12144025" ixy="-0.0006467757299999999" ixz="-5.7668584e-05" iyy="0.027586780999999998" iyz="0.027586780999999998" izz="0.10048465"/>
    </inertial>
    <visual>
      <origin rpy="0.0 0.0 0.0" xyz="0.0 0.0 0.0"/>
      <geometry>
        <mesh filename="/home/alaurenzi/code/ros2_ws/ros_src/iit-kyon-ros-pkg/kyon_urdf/meshes/mesh_hip-pitch.stl" scale="0.001 0.001 0.001"/>
      </geometry>
      <material name="kyon_orange"/>
    </visual>
    <visual>
      <origin rpy="0.0 0.0 0.0" xyz="0.0 0.0 0.0"/>
      <geometry>
        <mesh filename="/home/alaurenzi/code/ros2_ws/ros_src/iit-kyon-ros-pkg/kyon_urdf/meshes/mesh_hip-pitch_cover.stl" scale="0.001 0.001 0.001"/>
      </geometry>
      <material name="dark_grey"/>
    </visual>
  </link>
  <!-- joints -->
  <joint name="hip_roll_4" type="revolute">
    <parent link="pelvis"/>
    <child link="hip_roll_4_link"/>
    <origin rpy="0.0 -1.57079632679 0.0" xyz="-0.391 -0.0775 0.0"/>
    <axis xyz="0 0 -1"/>
    <limit effort="185" lower="-0.65" upper="0.65" velocity="7.6"/>
  </joint>
  <joint name="hip_pitch_4" type="revolute">
    <parent link="hip_roll_4_link"/>
    <child link="hip_pitch_4_link"/>
    <origin rpy="0.0 1.57079632679 -1.57079632679" xyz="0.0 0.04746 0.0"/>
    <axis xyz="0 0 -1"/>
    <limit effort="185" lower="-2.3426" upper="2.3426" velocity="7.6"/>
  </joint>
  <link name="knee_pitch_4_link">
    <inertial>
      <origin xyz="5.1193011000000004e-06 -0.10291594999999999 -0.0012895495"/>
      <mass value="0.70900216"/>
      <inertia ixx="0.012517512" ixy="-5.4385779e-07" ixz="1.4538899e-07" iyy="0.00080474409" iyz="0.001744629" izz="0.01230702"/>
    </inertial>
    <visual>
      <origin rpy="0.0 0.0 0.0" xyz="0.0 0.0 0.0"/>
      <geometry>
        <mesh filename="/home/alaurenzi/code/ros2_ws/ros_src/iit-kyon-ros-pkg/kyon_urdf/meshes/mesh_foot-leg.stl" scale="0.001 0.001 0.001"/>
      </geometry>
      <material name="dark_grey"/>
    </visual>
  </link>
  <joint name="knee_pitch_4" type="revolute">
    <parent link="hip_pitch_4_link"/>
    <child link="knee_pitch_4_link"/>
    <origin rpy="0.0 0.0 0.0" xyz="0.0 -0.34600000000000003 0.24606"/>
    <axis xyz="0 0 -1"/>
    <limit effort="185" lower="-3.2" upper="3.2" velocity="7.6"/>
  </joint>
  <link name="contact_4">
    <visual>
      <origin rpy="0 0 0" xyz="0 0 0"/>
      <geometry>
        <sphere radius="0.03"/>
      </geometry>
      <material name="white"/>
    </visual>
    <collision name="contact_4">
      <origin rpy="0 0 0" xyz="0 0 0"/>
      <geometry>
        <sphere radius="0.03"/>
      </geometry>
    </collision>
  </link>
  <joint name="contact_4_joint" type="fixed">
    <parent link="knee_pitch_4_link"/>
    <child link="contact_4"/>
    <origin rpy="1.57 0 2.356" xyz="-0.0 -0.3 0.054"/>
  </joint>
  <!-- <xacro:if value="${ADD_WHEELS}">
    <xacro:wheel_leg leg_num="${leg_num}" parent="hip_pitch_${leg_num}_link" origin_x="${origin_x}" origin_y="${origin_y}" mirror="${mirror}"/>
</xacro:if> -->
  <!-- ************ Control frames ************ -->
  <!--xacro:include filename="$(find pholus_urdf)/urdf/control_frames.urdf.xacro"/-->
  <link name="world"/>
  <joint name="reference" type="floating">
    <parent link="world"/>
    <child link="pelvis"/>
    <origin xyz="0 0 0.6"/>
  </joint>
</robot>
